<?xml version="1.0"?>
<robot xmlns:xacro="http://ros.org/wiki/xacro">
  <xacro:macro name="base" params="parent *joint_origin">
    <joint name="joint_0" type="revolute">
      <xacro:insert_block name="joint_origin"/>
      <axis xyz="0 0 1" />
      <parent link="${parent}"/>
      <child link="base_link"/>

      <limit effort="30" velocity="1.0" lower="-1.5" upper="1.5" />
    </joint>

    <link name="base_link">
      <visual>
        <geometry>
          <box size="0.01 0.01 0.01"/>
        </geometry>
      </visual>

      <collision>
        <geometry>
          <box size="0.01 0.01 0.01"/>
        </geometry>
      </collision>

      <inertial>
        <origin xyz="0 0 0"/>
        <mass value="0.6"/>
        <inertia ixx="1e-3" ixy="0" ixz="0" iyy="1e-3" iyz="0" izz="1e-3"/>
      </inertial>
    </link>
  </xacro:macro>
</robot>
