<?xml version="1.0"?>
<robot xmlns:xacro="http://ros.org/wiki/xacro">
  <xacro:macro name="arm" params="prefix parent *joint_origin *joint_axis">
    <joint name="joint_${prefix}" type="revolute">
      <xacro:insert_block name="joint_origin" />
      <xacro:insert_block name="joint_axis" />
      <parent link="${parent}" />
      <child link="arm_${prefix}" />

      <limit effort="30" velocity="1.0" lower="-1.5" upper="1.5" />
    </joint>
    
    <link name="arm_${prefix}">
      <visual>
        <origin xyz="0 0 0.05" rpy="0 0 0" />
        <geometry>
          <box size="0.01 0.01 0.1"/>
        </geometry>
      </visual>
      
      <collision>
        <origin xyz="0 0 0.05" rpy="0 0 0" />
        <geometry>
          <box size="0.01 0.01 0.1"/>
        </geometry>
      </collision>
      
      <inertial>
        <origin xyz="0.0 0.0 0.0" />
        <mass value="0.500"/>
        <inertia ixx="0.0013541667" ixy="0" ixz="0" iyy="0.0013541667" iyz="0" izz="0.0025"/>
      </inertial>
    </link>
  </xacro:macro>
</robot>
